--------------------
Failed to process https://github.com/GoogleChromeLabs/carlo repo
Traceback (most recent call last):
  File "/style-analyzer/lookout/style/format/benchmarks/top_repos_quality.py", line 385, in main
    vnodes_expected_number=vnodes_expected_number)
  File "/style-analyzer/lookout/style/format/benchmarks/top_repos_quality.py", line 231, in measure_quality
    config_json=json.dumps(review_config))
  File "/lookout-sdk-ml/lookout/core/test_helpers/server.py", line 77, in run
    return subprocess.run(command, stdout=sys.stdout, stderr=sys.stderr, check=True)
  File "/usr/lib/python3.6/subprocess.py", line 418, in run
    output=stdout, stderr=stderr)
subprocess.CalledProcessError: Command '['/tmp/lookout-sdk-ml-tests/server', 'review', 'ipv4://localhost:14554', '--from', '26262aad740b7255f17950251ae344b4823572a4', '--to', 'b8ce2bca042c757b13fc82a3e059980342ddd9a8', '--git-dir', '/tmp/top-repos-quality-repos-ve0wp6vt/carlo', '--log-level', 'warning', '--config-json', '{"style.format.analyzer.FormatAnalyzer": {"aggregate": true}}']' returned non-zero exit status 1.
--------------------
Failed to process https://github.com/reduxjs/redux repo
Traceback (most recent call last):
  File "/style-analyzer/lookout/style/format/benchmarks/top_repos_quality.py", line 385, in main
    vnodes_expected_number=vnodes_expected_number)
  File "/style-analyzer/lookout/style/format/benchmarks/top_repos_quality.py", line 231, in measure_quality
    config_json=json.dumps(review_config))
  File "/lookout-sdk-ml/lookout/core/test_helpers/server.py", line 77, in run
    return subprocess.run(command, stdout=sys.stdout, stderr=sys.stderr, check=True)
  File "/usr/lib/python3.6/subprocess.py", line 418, in run
    output=stdout, stderr=stderr)
subprocess.CalledProcessError: Command '['/tmp/lookout-sdk-ml-tests/server', 'review', 'ipv4://localhost:14554', '--from', 'b307091af4d7e846d9e5f080fb81caf4a8b4aab1', '--to', '902484ed735d38aec06683c847810a7218d8dba2', '--git-dir', '/tmp/top-repos-quality-repos-l7a9uzr6/redux', '--log-level', 'warning', '--config-json', '{"style.format.analyzer.FormatAnalyzer": {"aggregate": true}}']' returned non-zero exit status 1.
--------------------
Failed to process https://github.com/nodejs/citgm repo
Traceback (most recent call last):
  File "/style-analyzer/lookout/style/format/benchmarks/top_repos_quality.py", line 385, in main
    vnodes_expected_number=vnodes_expected_number)
  File "/style-analyzer/lookout/style/format/benchmarks/top_repos_quality.py", line 231, in measure_quality
    config_json=json.dumps(review_config))
  File "/lookout-sdk-ml/lookout/core/test_helpers/server.py", line 77, in run
    return subprocess.run(command, stdout=sys.stdout, stderr=sys.stderr, check=True)
  File "/usr/lib/python3.6/subprocess.py", line 418, in run
    output=stdout, stderr=stderr)
subprocess.CalledProcessError: Command '['/tmp/lookout-sdk-ml-tests/server', 'review', 'ipv4://localhost:14554', '--from', 'd21e2a87aaa9e9f50c6175eddc54054a32c64a24', '--to', '0c4c7ccdd1cad8ce9506e34ca523787ba18cafe2', '--git-dir', '/tmp/top-repos-quality-repos-fwyo13zf/citgm', '--log-level', 'warning', '--config-json', '{"style.format.analyzer.FormatAnalyzer": {"aggregate": true}}']' returned non-zero exit status 1.
--------------------
Failed to process https://github.com/segmentio/evergreen repo
Traceback (most recent call last):
  File "/style-analyzer/lookout/style/format/benchmarks/top_repos_quality.py", line 385, in main
    vnodes_expected_number=vnodes_expected_number)
  File "/style-analyzer/lookout/style/format/benchmarks/top_repos_quality.py", line 231, in measure_quality
    config_json=json.dumps(review_config))
  File "/lookout-sdk-ml/lookout/core/test_helpers/server.py", line 77, in run
    return subprocess.run(command, stdout=sys.stdout, stderr=sys.stderr, check=True)
  File "/usr/lib/python3.6/subprocess.py", line 418, in run
    output=stdout, stderr=stderr)
subprocess.CalledProcessError: Command '['/tmp/lookout-sdk-ml-tests/server', 'review', 'ipv4://localhost:14554', '--from', '1030eca5da38dce4e5047c23a3ea7fc0c246b8ce', '--to', 'ba22d511dad83c072842e47801ef42697d142f7c', '--git-dir', '/tmp/top-repos-quality-repos-a2nhf9ab/evergreen', '--log-level', 'warning', '--config-json', '{"style.format.analyzer.FormatAnalyzer": {"aggregate": true}}']' returned non-zero exit status 1.
--------------------
Failed to process https://github.com/30-seconds/30-seconds-of-code repo
Traceback (most recent call last):
  File "/style-analyzer/lookout/style/format/benchmarks/top_repos_quality.py", line 385, in main
    vnodes_expected_number=vnodes_expected_number)
  File "/style-analyzer/lookout/style/format/benchmarks/top_repos_quality.py", line 231, in measure_quality
    config_json=json.dumps(review_config))
  File "/lookout-sdk-ml/lookout/core/test_helpers/server.py", line 77, in run
    return subprocess.run(command, stdout=sys.stdout, stderr=sys.stderr, check=True)
  File "/usr/lib/python3.6/subprocess.py", line 418, in run
    output=stdout, stderr=stderr)
subprocess.CalledProcessError: Command '['/tmp/lookout-sdk-ml-tests/server', 'review', 'ipv4://localhost:14554', '--from', 'c8c60895e80b8bc90583502accdaa339b794609c', '--to', '3a122c9cfcbdc091227879a06a32bc67ccd0d35d', '--git-dir', '/tmp/top-repos-quality-repos-9h66n248/30-seconds-of-code', '--log-level', 'warning', '--config-json', '{"style.format.analyzer.FormatAnalyzer": {"aggregate": true}}']' returned non-zero exit status 1.
--------------------
Failed to process https://github.com/freeCodeCamp/freeCodeCamp repo
Traceback (most recent call last):
  File "/style-analyzer/lookout/style/format/benchmarks/top_repos_quality.py", line 385, in main
    vnodes_expected_number=vnodes_expected_number)
  File "/style-analyzer/lookout/style/format/benchmarks/top_repos_quality.py", line 231, in measure_quality
    config_json=json.dumps(review_config))
  File "/lookout-sdk-ml/lookout/core/test_helpers/server.py", line 77, in run
    return subprocess.run(command, stdout=sys.stdout, stderr=sys.stderr, check=True)
  File "/usr/lib/python3.6/subprocess.py", line 418, in run
    output=stdout, stderr=stderr)
subprocess.CalledProcessError: Command '['/tmp/lookout-sdk-ml-tests/server', 'review', 'ipv4://localhost:14554', '--from', 'c353c4c659c3dcb19524ba893f170805c931a44a', '--to', 'cf65516cce60645a417e44c4fcea7418ca920572', '--git-dir', '/tmp/top-repos-quality-repos-34zo2ik9/freeCodeCamp', '--log-level', 'warning', '--config-json', '{"style.format.analyzer.FormatAnalyzer": {"aggregate": true}}']' returned non-zero exit status 1.
--------------------
Failed to process https://github.com/storybooks/storybook repo
Traceback (most recent call last):
  File "/style-analyzer/lookout/style/format/benchmarks/top_repos_quality.py", line 385, in main
    vnodes_expected_number=vnodes_expected_number)
  File "/style-analyzer/lookout/style/format/benchmarks/top_repos_quality.py", line 231, in measure_quality
    config_json=json.dumps(review_config))
  File "/lookout-sdk-ml/lookout/core/test_helpers/server.py", line 77, in run
    return subprocess.run(command, stdout=sys.stdout, stderr=sys.stderr, check=True)
  File "/usr/lib/python3.6/subprocess.py", line 418, in run
    output=stdout, stderr=stderr)
subprocess.CalledProcessError: Command '['/tmp/lookout-sdk-ml-tests/server', 'review', 'ipv4://localhost:14554', '--from', '4c46f273719427788d568c037f285907aabd17f9', '--to', 'b28217f887af533a17cb1498887d6b4bd41bd643', '--git-dir', '/tmp/top-repos-quality-repos-dpjlswvc/storybook', '--log-level', 'warning', '--config-json', '{"style.format.analyzer.FormatAnalyzer": {"aggregate": true}}']' returned non-zero exit status 1.
--------------------
Failed to process https://github.com/atom/atom repo
Traceback (most recent call last):
  File "/style-analyzer/lookout/style/format/benchmarks/top_repos_quality.py", line 385, in main
    vnodes_expected_number=vnodes_expected_number)
  File "/style-analyzer/lookout/style/format/benchmarks/top_repos_quality.py", line 231, in measure_quality
    config_json=json.dumps(review_config))
  File "/lookout-sdk-ml/lookout/core/test_helpers/server.py", line 77, in run
    return subprocess.run(command, stdout=sys.stdout, stderr=sys.stderr, check=True)
  File "/usr/lib/python3.6/subprocess.py", line 418, in run
    output=stdout, stderr=stderr)
subprocess.CalledProcessError: Command '['/tmp/lookout-sdk-ml-tests/server', 'review', 'ipv4://localhost:14554', '--from', 'a3c320dd707b915da2192427bcceea166edbd6d4', '--to', '108b23210759a8c5b2f51ac99659be5dc31a7371', '--git-dir', '/tmp/top-repos-quality-repos-parkdo7_/atom', '--log-level', 'warning', '--config-json', '{"style.format.analyzer.FormatAnalyzer": {"aggregate": true}}']' returned non-zero exit status 1.
--------------------
Failed to process https://github.com/facebook/react-native repo
Traceback (most recent call last):
  File "/style-analyzer/lookout/style/format/benchmarks/top_repos_quality.py", line 385, in main
    vnodes_expected_number=vnodes_expected_number)
  File "/style-analyzer/lookout/style/format/benchmarks/top_repos_quality.py", line 231, in measure_quality
    config_json=json.dumps(review_config))
  File "/lookout-sdk-ml/lookout/core/test_helpers/server.py", line 77, in run
    return subprocess.run(command, stdout=sys.stdout, stderr=sys.stderr, check=True)
  File "/usr/lib/python3.6/subprocess.py", line 418, in run
    output=stdout, stderr=stderr)
subprocess.CalledProcessError: Command '['/tmp/lookout-sdk-ml-tests/server', 'review', 'ipv4://localhost:14554', '--from', '764dd511d21aa4dac815c59a7d72497267fde08a', '--to', '1850906e5e557beb2234a1708cfc5fe8e7b4f0bf', '--git-dir', '/tmp/top-repos-quality-repos-vto8kvea/react-native', '--log-level', 'warning', '--config-json', '{"style.format.analyzer.FormatAnalyzer": {"aggregate": true}}']' returned non-zero exit status 1.
--------------------
Failed to process https://github.com/facebook/react repo
Traceback (most recent call last):
  File "/style-analyzer/lookout/style/format/benchmarks/top_repos_quality.py", line 385, in main
    vnodes_expected_number=vnodes_expected_number)
  File "/style-analyzer/lookout/style/format/benchmarks/top_repos_quality.py", line 231, in measure_quality
    config_json=json.dumps(review_config))
  File "/lookout-sdk-ml/lookout/core/test_helpers/server.py", line 77, in run
    return subprocess.run(command, stdout=sys.stdout, stderr=sys.stderr, check=True)
  File "/usr/lib/python3.6/subprocess.py", line 418, in run
    output=stdout, stderr=stderr)
subprocess.CalledProcessError: Command '['/tmp/lookout-sdk-ml-tests/server', 'review', 'ipv4://localhost:14554', '--from', '8ced545e3df95afab6fa35bc29f9320bafbcef26', '--to', '1034e26fe5e42ba07492a736da7bdf5bf2108bc6', '--git-dir', '/tmp/top-repos-quality-repos-rhop47za/react', '--log-level', 'warning', '--config-json', '{"style.format.analyzer.FormatAnalyzer": {"aggregate": true}}']' returned non-zero exit status 1.
--------------------
Failed to process https://github.com/meteor/meteor repo
Traceback (most recent call last):
  File "/style-analyzer/lookout/style/format/benchmarks/top_repos_quality.py", line 385, in main
    vnodes_expected_number=vnodes_expected_number)
  File "/style-analyzer/lookout/style/format/benchmarks/top_repos_quality.py", line 231, in measure_quality
    config_json=json.dumps(review_config))
  File "/lookout-sdk-ml/lookout/core/test_helpers/server.py", line 77, in run
    return subprocess.run(command, stdout=sys.stdout, stderr=sys.stderr, check=True)
  File "/usr/lib/python3.6/subprocess.py", line 418, in run
    output=stdout, stderr=stderr)
subprocess.CalledProcessError: Command '['/tmp/lookout-sdk-ml-tests/server', 'review', 'ipv4://localhost:14554', '--from', '62fa9927ce34cff064cc3991439553e7c52b5258', '--to', 'c3309b123a7220ac24cbe73661184ee946bca01f', '--git-dir', '/tmp/top-repos-quality-repos-yuywv07v/meteor', '--log-level', 'warning', '--config-json', '{"style.format.analyzer.FormatAnalyzer": {"aggregate": true}}']' returned non-zero exit status 1.
